2024-09-30 10:29:32,515 - ERROR - An unexpected e occurred: ('AttributeError', "'ImageHandling' object has no attribute 'app_logger'")
2024-09-30 10:29:38,473 - ERROR - An unexpected e occurred: ('AttributeError', "'ImageHandling' object has no attribute 'app_logger'")
2024-09-30 10:29:58,994 - ERROR - An unexpected e occurred: ('TypeError', "'Logger' object is not callable")
2024-09-30 10:30:04,952 - ERROR - An unexpected e occurred: ('TypeError', "'Logger' object is not callable")
2024-09-30 10:45:51,459 - ERROR - An unexpected e occurred: ('UnidentifiedImageError', 'cannot identify image file <_io.BytesIO object at 0x7f23764dddb0>')
2024-09-30 10:45:51,460 - ERROR - An unexpected e occurred: ('UnidentifiedImageError', 'cannot identify image file <_io.BytesIO object at 0x7f23764dddb0>')
2024-09-30 10:45:51,461 - ERROR - An unexpected e occurred: ('UnidentifiedImageError', 'cannot identify image file <_io.BytesIO object at 0x7f23764dddb0>')
2024-09-30 13:38:55,597 - ERROR - An unexpected e occurred: ('NameError', "name 'create_csv_agent' is not defined")
2024-09-30 13:41:11,997 - ERROR - An unexpected e occurred: ('FileNotFoundError', "[Errno 2] No such file or directory: 'titanic.csv'")
2024-09-30 13:49:53,752 - ERROR - An unexpected e occurred: ('FileNotFoundError', "[Errno 2] No such file or directory: 'titanic.csv'")
2024-09-30 13:51:32,988 - ERROR - An unexpected e occurred: ('FileNotFoundError', "[Errno 2] No such file or directory: '/export/home/saallam/image_handling/walter-image-handling/titanic.csv'")
2024-09-30 13:53:15,891 - ERROR - An unexpected e occurred: ('FileNotFoundError', "[Errno 2] No such file or directory: '/export/home/saallam/image_handling/walter-image-handling/titanic.csv'")
2024-09-30 13:54:33,115 - ERROR - An unexpected e occurred: ('ParserError', 'Error tokenizing data. C error: Expected 1 fields in line 18, saw 2587\n')
2024-09-30 13:59:07,620 - ERROR - An unexpected e occurred: ('ValidationError', '1 validation error for PythonAstREPLTool\n__root__\n  This tool relies on Python 3.9 or higher (as it uses new functionality in the `ast` module, you have Python version: 3.8.10 (default, Sep 11 2024, 16:02:53) \n[GCC 9.4.0] (type=value_error)')
2024-09-30 14:21:42,456 - ERROR - An unexpected e occurred: ('ValidationError', '1 validation error for PythonAstREPLTool\n__root__\n  This tool relies on Python 3.9 or higher (as it uses new functionality in the `ast` module, you have Python version: 3.8.10 (default, Sep 11 2024, 16:02:53) \n[GCC 9.4.0] (type=value_error)')
2024-09-30 14:28:35,917 - ERROR - An unexpected e occurred: ('ValidationError', '1 validation error for PythonAstREPLTool\n__root__\n  This tool relies on Python 3.9 or higher (as it uses new functionality in the `ast` module, you have Python version: 3.8.10 (default, Sep 11 2024, 16:02:53) \n[GCC 9.4.0] (type=value_error)')
2024-09-30 14:36:27,630 - ERROR - An unexpected e occurred: ('TypeError', 'string indices must be integers')
2024-09-30 14:36:27,631 - ERROR - An unexpected e occurred: ('TypeError', 'string indices must be integers')
2024-09-30 14:36:27,640 - ERROR - An unexpected e occurred: ('TypeError', 'string indices must be integers')
2024-09-30 14:36:27,642 - ERROR - An unexpected e occurred: ('TypeError', 'string indices must be integers')
2024-09-30 14:42:50,247 - ERROR - An unexpected e occurred: ('TypeError', 'string indices must be integers')
2024-09-30 14:42:50,248 - ERROR - An unexpected e occurred: ('TypeError', 'string indices must be integers')
2024-09-30 14:42:50,444 - ERROR - An unexpected e occurred: ('TypeError', 'string indices must be integers')
2024-09-30 14:42:50,445 - ERROR - An unexpected e occurred: ('TypeError', 'string indices must be integers')
2024-09-30 14:44:47,688 - ERROR - An unexpected e occurred: ('NameError', "name 'image_urls' is not defined")
2024-09-30 14:44:47,689 - ERROR - An unexpected e occurred: ('NameError', "name 'image_urls' is not defined")
2024-09-30 14:44:47,713 - ERROR - An unexpected e occurred: ('NameError', "name 'image_urls' is not defined")
2024-09-30 14:44:47,713 - ERROR - An unexpected e occurred: ('NameError', "name 'image_urls' is not defined")
2024-09-30 14:45:17,419 - ERROR - An unexpected e occurred: ('UnidentifiedImageError', 'cannot identify image file <_io.BytesIO object at 0x7f4fc0f9ed10>')
2024-09-30 14:45:17,420 - ERROR - An unexpected e occurred: ('UnidentifiedImageError', 'cannot identify image file <_io.BytesIO object at 0x7f4fc0f9ed10>')
2024-09-30 14:45:17,420 - ERROR - An unexpected e occurred: ('UnidentifiedImageError', 'cannot identify image file <_io.BytesIO object at 0x7f4fc0f9ed10>')
2024-09-30 15:54:29,447 - ERROR - An unexpected e occurred: ('ImportError', 'pandas package not found, please install with `pip install pandas`.')
2024-09-30 15:54:29,447 - ERROR - An unexpected e occurred: ('ImportError', 'pandas package not found, please install with `pip install pandas`.')
2024-09-30 15:57:18,084 - ERROR - An unexpected e occurred: ('ImportError', "Missing optional dependency 'tabulate'.  Use pip or conda to install tabulate.")
2024-09-30 15:57:18,084 - ERROR - An unexpected e occurred: ('ImportError', "Missing optional dependency 'tabulate'.  Use pip or conda to install tabulate.")
